{
 "cells": [
  {
   "cell_type": "code",
   "execution_count": 7,
   "metadata": {},
   "outputs": [
    {
     "name": "stdout",
     "output_type": "stream",
     "text": [
      "{'with mask': 0, 'without mask': 1}\n",
      "['with mask', 'without mask']\n",
      "[0, 1]\n"
     ]
    }
   ],
   "source": [
    "import cv2,os\n",
    "\n",
    "data_path='D:\\Code\\Python\\Face Mask Detection\\dataset'\n",
    "categories=os.listdir(data_path)\n",
    "labels=[i for i in range(len(categories))]\n",
    "\n",
    "label_dict=dict(zip(categories,labels))\n",
    "\n",
    "print(label_dict)\n",
    "print(categories)\n",
    "print(labels)"
   ]
  },
  {
   "cell_type": "code",
   "execution_count": 9,
   "metadata": {},
   "outputs": [],
   "source": [
    "\n",
    "img_size=100\n",
    "data=[]\n",
    "target=[]"
   ]
  },
  {
   "cell_type": "code",
   "execution_count": 10,
   "metadata": {},
   "outputs": [],
   "source": [
    "\n",
    "\n",
    "for category in categories:\n",
    "    folder_path=os.path.join(data_path,category)\n",
    "    img_names=os.listdir(folder_path)\n",
    "        \n",
    "    for img_name in img_names:\n",
    "        img_path=os.path.join(folder_path,img_name)\n",
    "        img=cv2.imread(img_path)\n",
    "\n",
    "        try:\n",
    "            gray=cv2.cvtColor(img,cv2.COLOR_BGR2GRAY)           \n",
    "            \n",
    "            resized=cv2.resize(gray,(img_size,img_size))\n",
    "           \n",
    "            data.append(resized)\n",
    "            target.append(label_dict[category])\n",
    "            \n",
    "\n",
    "        except Exception as e:\n",
    "            print('Exception:',e)"
   ]
  },
  {
   "cell_type": "code",
   "execution_count": 13,
   "metadata": {},
   "outputs": [],
   "source": [
    "import numpy as np\n",
    "\n",
    "data=np.array(data)/255.0\n",
    "data=np.reshape(data,(data.shape[0],img_size,img_size,1))\n",
    "target=np.array(target)\n",
    "\n",
    "from keras.utils import np_utils\n",
    "\n",
    "new_target=np_utils.to_categorical(target)"
   ]
  },
  {
   "cell_type": "code",
   "execution_count": 14,
   "metadata": {},
   "outputs": [],
   "source": [
    "np.save('data',data)\n",
    "np.save('target',new_target)"
   ]
  },
  {
   "cell_type": "code",
   "execution_count": 34,
   "metadata": {},
   "outputs": [],
   "source": [
    "import numpy as np\n",
    "\n",
    "data=\"D:\\Code\\Python\\Face Mask Detection\\data.npy\"\n",
    "target=\"D:\\Code\\Python\\Face Mask Detection\\target.npy\""
   ]
  },
  {
   "cell_type": "code",
   "execution_count": 22,
   "metadata": {},
   "outputs": [],
   "source": [
    "from keras.models import Sequential\n",
    "from keras.layers import Dense,Activation,Flatten,Dropout\n",
    "from keras.layers import Conv2D,MaxPooling2D\n",
    "from keras.callbacks import ModelCheckpoint\n",
    "\n",
    "model=Sequential()\n",
    "\n",
    "model.add(Conv2D(200,(3,3),input_shape=data.shape[1:]))\n",
    "model.add(Activation('relu'))\n",
    "model.add(MaxPooling2D(pool_size=(2,2)))\n",
    "\n",
    "\n",
    "model.add(Conv2D(100,(3,3)))\n",
    "model.add(Activation('relu'))\n",
    "model.add(MaxPooling2D(pool_size=(2,2)))\n",
    "\n",
    "\n",
    "model.add(Flatten())\n",
    "model.add(Dropout(0.5))\n",
    "\n",
    "model.add(Dense(50,activation='relu'))\n",
    "\n",
    "model.add(Dense(2,activation='softmax'))\n",
    "\n",
    "\n",
    "model.compile(loss='categorical_crossentropy',optimizer='adam',metrics=['accuracy'])"
   ]
  },
  {
   "cell_type": "code",
   "execution_count": 24,
   "metadata": {},
   "outputs": [],
   "source": [
    "from sklearn.model_selection import train_test_split\n",
    "\n",
    "train_data,test_data,train_target,test_target=train_test_split(data,target,test_size=0.1)"
   ]
  },
  {
   "cell_type": "code",
   "execution_count": 35,
   "metadata": {},
   "outputs": [
    {
     "name": "stdout",
     "output_type": "stream",
     "text": [
      "Epoch 1/20\n"
     ]
    },
    {
     "ename": "ValueError",
     "evalue": "in user code:\n\n    File \"C:\\Users\\hp\\AppData\\Local\\Packages\\PythonSoftwareFoundation.Python.3.10_qbz5n2kfra8p0\\LocalCache\\local-packages\\Python310\\site-packages\\keras\\engine\\training.py\", line 1160, in train_function  *\n        return step_function(self, iterator)\n    File \"C:\\Users\\hp\\AppData\\Local\\Packages\\PythonSoftwareFoundation.Python.3.10_qbz5n2kfra8p0\\LocalCache\\local-packages\\Python310\\site-packages\\keras\\engine\\training.py\", line 1146, in step_function  **\n        outputs = model.distribute_strategy.run(run_step, args=(data,))\n    File \"C:\\Users\\hp\\AppData\\Local\\Packages\\PythonSoftwareFoundation.Python.3.10_qbz5n2kfra8p0\\LocalCache\\local-packages\\Python310\\site-packages\\keras\\engine\\training.py\", line 1135, in run_step  **\n        outputs = model.train_step(data)\n    File \"C:\\Users\\hp\\AppData\\Local\\Packages\\PythonSoftwareFoundation.Python.3.10_qbz5n2kfra8p0\\LocalCache\\local-packages\\Python310\\site-packages\\keras\\engine\\training.py\", line 994, in train_step\n        loss = self.compute_loss(x, y, y_pred, sample_weight)\n    File \"C:\\Users\\hp\\AppData\\Local\\Packages\\PythonSoftwareFoundation.Python.3.10_qbz5n2kfra8p0\\LocalCache\\local-packages\\Python310\\site-packages\\keras\\engine\\training.py\", line 1052, in compute_loss\n        return self.compiled_loss(\n    File \"C:\\Users\\hp\\AppData\\Local\\Packages\\PythonSoftwareFoundation.Python.3.10_qbz5n2kfra8p0\\LocalCache\\local-packages\\Python310\\site-packages\\keras\\engine\\compile_utils.py\", line 265, in __call__\n        loss_value = loss_obj(y_t, y_p, sample_weight=sw)\n    File \"C:\\Users\\hp\\AppData\\Local\\Packages\\PythonSoftwareFoundation.Python.3.10_qbz5n2kfra8p0\\LocalCache\\local-packages\\Python310\\site-packages\\keras\\losses.py\", line 152, in __call__\n        losses = call_fn(y_true, y_pred)\n    File \"C:\\Users\\hp\\AppData\\Local\\Packages\\PythonSoftwareFoundation.Python.3.10_qbz5n2kfra8p0\\LocalCache\\local-packages\\Python310\\site-packages\\keras\\losses.py\", line 272, in call  **\n        return ag_fn(y_true, y_pred, **self._fn_kwargs)\n    File \"C:\\Users\\hp\\AppData\\Local\\Packages\\PythonSoftwareFoundation.Python.3.10_qbz5n2kfra8p0\\LocalCache\\local-packages\\Python310\\site-packages\\keras\\losses.py\", line 1990, in categorical_crossentropy\n        return backend.categorical_crossentropy(\n    File \"C:\\Users\\hp\\AppData\\Local\\Packages\\PythonSoftwareFoundation.Python.3.10_qbz5n2kfra8p0\\LocalCache\\local-packages\\Python310\\site-packages\\keras\\backend.py\", line 5529, in categorical_crossentropy\n        target.shape.assert_is_compatible_with(output.shape)\n\n    ValueError: Shapes (None, 1) and (None, 2) are incompatible\n",
     "output_type": "error",
     "traceback": [
      "\u001b[1;31m---------------------------------------------------------------------------\u001b[0m",
      "\u001b[1;31mValueError\u001b[0m                                Traceback (most recent call last)",
      "Cell \u001b[1;32mIn [35], line 2\u001b[0m\n\u001b[0;32m      1\u001b[0m checkpoint \u001b[39m=\u001b[39m ModelCheckpoint(\u001b[39m'\u001b[39m\u001b[39mmodel-\u001b[39m\u001b[39m{epoch:03d}\u001b[39;00m\u001b[39m.model\u001b[39m\u001b[39m'\u001b[39m,monitor\u001b[39m=\u001b[39m\u001b[39m'\u001b[39m\u001b[39mval_loss\u001b[39m\u001b[39m'\u001b[39m,verbose\u001b[39m=\u001b[39m\u001b[39m0\u001b[39m,save_best_only\u001b[39m=\u001b[39m\u001b[39mTrue\u001b[39;00m,mode\u001b[39m=\u001b[39m\u001b[39m'\u001b[39m\u001b[39mauto\u001b[39m\u001b[39m'\u001b[39m)\n\u001b[1;32m----> 2\u001b[0m history\u001b[39m=\u001b[39mmodel\u001b[39m.\u001b[39;49mfit(train_data,train_target,epochs\u001b[39m=\u001b[39;49m\u001b[39m20\u001b[39;49m,callbacks\u001b[39m=\u001b[39;49m[checkpoint],validation_split\u001b[39m=\u001b[39;49m\u001b[39m0.2\u001b[39;49m)\n",
      "File \u001b[1;32m~\\AppData\\Local\\Packages\\PythonSoftwareFoundation.Python.3.10_qbz5n2kfra8p0\\LocalCache\\local-packages\\Python310\\site-packages\\keras\\utils\\traceback_utils.py:70\u001b[0m, in \u001b[0;36mfilter_traceback.<locals>.error_handler\u001b[1;34m(*args, **kwargs)\u001b[0m\n\u001b[0;32m     67\u001b[0m     filtered_tb \u001b[39m=\u001b[39m _process_traceback_frames(e\u001b[39m.\u001b[39m__traceback__)\n\u001b[0;32m     68\u001b[0m     \u001b[39m# To get the full stack trace, call:\u001b[39;00m\n\u001b[0;32m     69\u001b[0m     \u001b[39m# `tf.debugging.disable_traceback_filtering()`\u001b[39;00m\n\u001b[1;32m---> 70\u001b[0m     \u001b[39mraise\u001b[39;00m e\u001b[39m.\u001b[39mwith_traceback(filtered_tb) \u001b[39mfrom\u001b[39;00m \u001b[39mNone\u001b[39m\n\u001b[0;32m     71\u001b[0m \u001b[39mfinally\u001b[39;00m:\n\u001b[0;32m     72\u001b[0m     \u001b[39mdel\u001b[39;00m filtered_tb\n",
      "File \u001b[1;32m~\\AppData\\Local\\Temp\\__autograph_generated_file7xmcrmo0.py:15\u001b[0m, in \u001b[0;36mouter_factory.<locals>.inner_factory.<locals>.tf__train_function\u001b[1;34m(iterator)\u001b[0m\n\u001b[0;32m     13\u001b[0m \u001b[39mtry\u001b[39;00m:\n\u001b[0;32m     14\u001b[0m     do_return \u001b[39m=\u001b[39m \u001b[39mTrue\u001b[39;00m\n\u001b[1;32m---> 15\u001b[0m     retval_ \u001b[39m=\u001b[39m ag__\u001b[39m.\u001b[39mconverted_call(ag__\u001b[39m.\u001b[39mld(step_function), (ag__\u001b[39m.\u001b[39mld(\u001b[39mself\u001b[39m), ag__\u001b[39m.\u001b[39mld(iterator)), \u001b[39mNone\u001b[39;00m, fscope)\n\u001b[0;32m     16\u001b[0m \u001b[39mexcept\u001b[39;00m:\n\u001b[0;32m     17\u001b[0m     do_return \u001b[39m=\u001b[39m \u001b[39mFalse\u001b[39;00m\n",
      "\u001b[1;31mValueError\u001b[0m: in user code:\n\n    File \"C:\\Users\\hp\\AppData\\Local\\Packages\\PythonSoftwareFoundation.Python.3.10_qbz5n2kfra8p0\\LocalCache\\local-packages\\Python310\\site-packages\\keras\\engine\\training.py\", line 1160, in train_function  *\n        return step_function(self, iterator)\n    File \"C:\\Users\\hp\\AppData\\Local\\Packages\\PythonSoftwareFoundation.Python.3.10_qbz5n2kfra8p0\\LocalCache\\local-packages\\Python310\\site-packages\\keras\\engine\\training.py\", line 1146, in step_function  **\n        outputs = model.distribute_strategy.run(run_step, args=(data,))\n    File \"C:\\Users\\hp\\AppData\\Local\\Packages\\PythonSoftwareFoundation.Python.3.10_qbz5n2kfra8p0\\LocalCache\\local-packages\\Python310\\site-packages\\keras\\engine\\training.py\", line 1135, in run_step  **\n        outputs = model.train_step(data)\n    File \"C:\\Users\\hp\\AppData\\Local\\Packages\\PythonSoftwareFoundation.Python.3.10_qbz5n2kfra8p0\\LocalCache\\local-packages\\Python310\\site-packages\\keras\\engine\\training.py\", line 994, in train_step\n        loss = self.compute_loss(x, y, y_pred, sample_weight)\n    File \"C:\\Users\\hp\\AppData\\Local\\Packages\\PythonSoftwareFoundation.Python.3.10_qbz5n2kfra8p0\\LocalCache\\local-packages\\Python310\\site-packages\\keras\\engine\\training.py\", line 1052, in compute_loss\n        return self.compiled_loss(\n    File \"C:\\Users\\hp\\AppData\\Local\\Packages\\PythonSoftwareFoundation.Python.3.10_qbz5n2kfra8p0\\LocalCache\\local-packages\\Python310\\site-packages\\keras\\engine\\compile_utils.py\", line 265, in __call__\n        loss_value = loss_obj(y_t, y_p, sample_weight=sw)\n    File \"C:\\Users\\hp\\AppData\\Local\\Packages\\PythonSoftwareFoundation.Python.3.10_qbz5n2kfra8p0\\LocalCache\\local-packages\\Python310\\site-packages\\keras\\losses.py\", line 152, in __call__\n        losses = call_fn(y_true, y_pred)\n    File \"C:\\Users\\hp\\AppData\\Local\\Packages\\PythonSoftwareFoundation.Python.3.10_qbz5n2kfra8p0\\LocalCache\\local-packages\\Python310\\site-packages\\keras\\losses.py\", line 272, in call  **\n        return ag_fn(y_true, y_pred, **self._fn_kwargs)\n    File \"C:\\Users\\hp\\AppData\\Local\\Packages\\PythonSoftwareFoundation.Python.3.10_qbz5n2kfra8p0\\LocalCache\\local-packages\\Python310\\site-packages\\keras\\losses.py\", line 1990, in categorical_crossentropy\n        return backend.categorical_crossentropy(\n    File \"C:\\Users\\hp\\AppData\\Local\\Packages\\PythonSoftwareFoundation.Python.3.10_qbz5n2kfra8p0\\LocalCache\\local-packages\\Python310\\site-packages\\keras\\backend.py\", line 5529, in categorical_crossentropy\n        target.shape.assert_is_compatible_with(output.shape)\n\n    ValueError: Shapes (None, 1) and (None, 2) are incompatible\n"
     ]
    }
   ],
   "source": [
    "checkpoint = ModelCheckpoint('model-{epoch:03d}.model',monitor='val_loss',verbose=0,save_best_only=True,mode='auto')\n",
    "history=model.fit(train_data,train_target,epochs=20,callbacks=[checkpoint],validation_split=0.2)"
   ]
  },
  {
   "cell_type": "code",
   "execution_count": 27,
   "metadata": {},
   "outputs": [],
   "source": [
    "from keras.models import load_model\n",
    "import cv2\n",
    "import numpy as np"
   ]
  },
  {
   "cell_type": "code",
   "execution_count": 29,
   "metadata": {},
   "outputs": [],
   "source": [
    "model = load_model(\"D:\\Code\\Python\\Face Mask Detection\\model-017.model\")\n",
    "\n",
    "face_clsfr=cv2.CascadeClassifier(\"D:\\Code\\Python\\Face Mask Detection\\haarcascade_frontalface_default.xml\")\n",
    "\n",
    "source=cv2.VideoCapture(0)\n",
    "\n",
    "labels_dict={0:'MASK',1:'NO MASK'}\n",
    "color_dict={0:(0,255,0),1:(0,0,255)}"
   ]
  }
 ],
 "metadata": {
  "kernelspec": {
   "display_name": "Python 3.10.7 64-bit (microsoft store)",
   "language": "python",
   "name": "python3"
  },
  "language_info": {
   "codemirror_mode": {
    "name": "ipython",
    "version": 3
   },
   "file_extension": ".py",
   "mimetype": "text/x-python",
   "name": "python",
   "nbconvert_exporter": "python",
   "pygments_lexer": "ipython3",
   "version": "3.10.7"
  },
  "orig_nbformat": 4,
  "vscode": {
   "interpreter": {
    "hash": "ba37d69516b96b2df66115ef342e83722e1a1518f5d2e0ee41eb08141fa2fe2a"
   }
  }
 },
 "nbformat": 4,
 "nbformat_minor": 2
}
